Workbook

Sheet 59مخالفة
A1: ت | B1: نوع المخالفة | C1: الايسر | D1: الايسر مبالغ | E1: الايمن | F1: الأيمن مبالغ | G1: شرق نينوى | H1: شرق نينوى مبالغ | I1: غرب نينوى | J1: غرب نينوى مبالغ | K1: تلعفر | L1: تلعفر مبالغ | M1: سنجار | N1: سنجار مبالغ | O1: ربيعة | P1: ربيعة مبالغ | Q1: القيارة | R1: القيارة مبالغ | S1: زمار | T1: زمار مبالغ | U1: الحمدانية | V1: الحمدانية مبالغ | W1: الاوزان | X1: الاوزان مبالغ | Y1: العدد/ الغرامات | Z1: حجز مركبات | AA1: حجز دراجات | AB1: مبلغ الغرامات
A3: 1 | B3: عدم الامتثال للإشارة الضوئية او اشارة رجل المرور التنظيمية | Y3: =SUM(C3,E3,G3,I3,K3,M3,O3,Q3,S3,U3,W3) -> 0 | AB3: =SUM(D3,F3,H3,J3,L3,N3,P3,R3,T3,V3,X3) -> 0
A4: 2 | B4: قيادة مركبة بإهمال ورعونة | Y4: =SUM(C4,E4,G4,I4,K4,M4,O4,Q4,S4,U4,W4) -> 0 | AB4: =SUM(D4,F4,H4,J4,L4,N4,P4,R4,T4,V4,X4) -> 0
A5: 3 | B5: قيادة مركبة بسرعة تزيد عن السرعة المقررة قانونا | Y5: =SUM(C5,E5,G5,I5,K5,M5,O5,Q5,S5,U5,W5) -> 0 | AB5: =SUM(D5,F5,H5,J5,L5,N5,P5,R5,T5,V5,X5) -> 0
A6: 4 | B6: مخالفة قواعد السير والمرور على الطرق السريع | Y6: =SUM(C6,E6,G6,I6,K6,M6,O6,Q6,S6,U6,W6) -> 0 | AB6: =SUM(D6,F6,H6,J6,L6,N6,P6,R6,T6,V6,X6) -> 0
A7: 5 | B7: السير عكس الاتجاه | Y7: =SUM(C7,E7,G7,I7,K7,M7,O7,Q7,S7,U7,W7) -> 0 | AB7: =SUM(D7,F7,H7,J7,L7,N7,P7,R7,T7,V7,X7) -> 0
A8: 6 | B8: الزجاج المضلل والستائر | Y8: =SUM(C8,E8,G8,I8,K8,M8,O8,Q8,S8,U8,W8) -> 0 | AB8: =SUM(D8,F8,H8,J8,L8,N8,P8,R8,T8,V8,X8) -> 0
A9: 7 | B9: عدم تثبيت لوحات مفردة او مزدوجة (بدون لوحة تسجيل) | Y9: =SUM(C9,E9,G9,I9,K9,M9,O9,Q9,S9,U9,W9) -> 0 | AB9: =SUM(D9,F9,H9,J9,L9,N9,P9,R9,T9,V9,X9) -> 0
A10: 8 | B10: عدم وضع غطاء الحمولة | Y10: =SUM(C10,E10,G10,I10,K10,M10,O10,Q10,S10,U10,W10) -> 0 | AB10: =SUM(D10,F10,H10,J10,L10,N10,P10,R10,T10,V10,X10) -> 0
A11: 9 | B11: ارتفاع الحمولة | W11: 15 | X11: 1400000 | Y11: =SUM(C11,E11,G11,I11,K11,M11,O11,Q11,S11,U11,W11) -> 15 | AB11: =SUM(D11,F11,H11,J11,L11,N11,P11,R11,T11,V11,X11) -> 1400000
A12: 10 | B12: عدم مراجعة البائع او المشتري لنقل ملكية المركبة خلال (30) يوم | Y12: =SUM(C12,E12,G12,I12,K12,M12,O12,Q12,S12,U12,W12) -> 0 | AB12: =SUM(D12,F12,H12,J12,L12,N12,P12,R12,T12,V12,X12) -> 0
A13: 11 | B13: تنظيم اكثر من عقد واحد للمركبة ذاتها من قبل البائع | Y13: =SUM(C13,E13,G13,I13,K13,M13,O13,Q13,S13,U13,W13) -> 0 | AB13: =SUM(D13,F13,H13,J13,L13,N13,P13,R13,T13,V13,X13) -> 0
A14: 12 | B14: قيادة مركبة بإجازة سوق غير مختصة بنوع المركبة | C14: 3 | D14: 150000 | E14: 16 | F14: 800000 | G14: 3 | H14: 150000 | Q14: 5 | R14: 250000 | S14: 2 | T14: 100000 | U14: 12 | V14: 600000 | Y14: =SUM(C14,E14,G14,I14,K14,M14,O14,Q14,S14,U14,W14) -> 41 | AB14: =SUM(D14,F14,H14,J14,L14,N14,P14,R14,T14,V14,X14) -> 2050000
A15: 13 | B15: عدم (حمل اجازة السوق او السنوية ) او الامتناع عن اعطائها | C15: 6 | D15: 300000 | E15: 19 | F15: 950000 | K15: 4 | L15: 200000 | O15: 4 | P15: 200000 | Q15: 4 | R15: 200000 | S15: 3 | T15: 150000 | U15: 9 | V15: 450000 | Y15: =SUM(C15,E15,G15,I15,K15,M15,O15,Q15,S15,U15,W15) -> 49 | AB15: =SUM(D15,F15,H15,J15,L15,N15,P15,R15,T15,V15,X15) -> 2450000
A16: 14 | B16: عدم ( تجديد اجازة السوق او السنوية ) بعد مرور (30) يوم | C16: 15 | D16: 750000 | E16: 10 | F16: 500000 | G16: 11 | H16: 550000 | I16: 3 | J16: 150000 | K16: 19 | L16: 950000 | M16: 4 | N16: 200000 | O16: 4 | P16: 200000 | S16: 2 | T16: 100000 | U16: 17 | V16: 850000 | Y16: =SUM(C16,E16,G16,I16,K16,M16,O16,Q16,S16,U16,W16) -> 85 | AB16: =SUM(D16,F16,H16,J16,L16,N16,P16,R16,T16,V16,X16) -> 4250000
A17: 15 | B17: عدم مراجعة دائرة التسجيل لتسجيل المركبة بعد (30) يوم على كتاب البيع او التسجيل | Y17: =SUM(C17,E17,G17,I17,K17,M17,O17,Q17,S17,U17,W17) -> 0 | AB17: =SUM(D17,F17,H17,J17,L17,N17,P17,R17,T17,V17,X17) -> 0
A18: 16 | B18: الوقوف الممنوع | C18: 125 | D18: 6250000 | E18: 64 | F18: 3200000 | G18: 3 | H18: 150000 | K18: 1 | L18: 50000 | M18: 2 | N18: 100000 | O18: 3 | P18: 150000 | Q18: 1 | R18: 50000 | Y18: =SUM(C18,E18,G18,I18,K18,M18,O18,Q18,S18,U18,W18) -> 199 | AB18: =SUM(D18,F18,H18,J18,L18,N18,P18,R18,T18,V18,X18) -> 9950000
A19: 17 | B19: عدم اعطاء الاسبقية للمشاة في منطقة العبور | Y19: =SUM(C19,E19,G19,I19,K19,M19,O19,Q19,S19,U19,W19) -> 0 | AB19: =SUM(D19,F19,H19,J19,L19,N19,P19,R19,T19,V19,X19) -> 0
A20: 18 | B20: عدم ارتداء حزام الامان( للسائق او الراكب الذي بجانبه ) او جلوس الاطفال دون سن (8) سنوات في المقعد الامامي للسيارة | E20: 6 | F20: 300000 | G20: 6 | H20: 300000 | I20: 3 | J20: 150000 | K20: 2 | L20: 100000 | U20: 9 | V20: 450000 | Y20: =SUM(C20,E20,G20,I20,K20,M20,O20,Q20,S20,U20,W20) -> 26 | AB20: =SUM(D20,F20,H20,J20,L20,N20,P20,R20,T20,V20,X20) -> 1300000
A21: 19 | B21: استعمال الضوء العالي | M21: 3 | N21: 150000 | Y21: =SUM(C21,E21,G21,I21,K21,M21,O21,Q21,S21,U21,W21) -> 3 | AB21: =SUM(D21,F21,H21,J21,L21,N21,P21,R21,T21,V21,X21) -> 150000
A22: 20 | B22: استعمال جهاز التنبيه الهوائي او اخر غير متواجد في المنشأ | Y22: =SUM(C22,E22,G22,I22,K22,M22,O22,Q22,S22,U22,W22) -> 0 | AB22: =SUM(D22,F22,H22,J22,L22,N22,P22,R22,T22,V22,X22) -> 0
A23: 21 | B23: الاجتياز الخاطئ من جهة اليمين | Y23: =SUM(C23,E23,G23,I23,K23,M23,O23,Q23,S23,U23,W23) -> 0 | AB23: =SUM(D23,F23,H23,J23,L23,N23,P23,R23,T23,V23,X23) -> 0
A24: 22 | B24: وضع ملصقات زينة | E24: 2 | F24: 100000 | K24: 1 | L24: 50000 | Y24: =SUM(C24,E24,G24,I24,K24,M24,O24,Q24,S24,U24,W24) -> 3 | AB24: =SUM(D24,F24,H24,J24,L24,N24,P24,R24,T24,V24,X24) -> 150000
A25: 23 | B25: نقل ركاب على جوانب العجلة او جزء خارجي منها او اكثر من استيعابها | Y25: =SUM(C25,E25,G25,I25,K25,M25,O25,Q25,S25,U25,W25) -> 0 | AB25: =SUM(D25,F25,H25,J25,L25,N25,P25,R25,T25,V25,X25) -> 0
A26: 24 | B26: قيادة الدراجات النارية التي سعة محركها تقل عن (40 cc) في الشوارع الرئيسية | E26: 3 | F26: 150000 | Y26: =SUM(C26,E26,G26,I26,K26,M26,O26,Q26,S26,U26,W26) -> 3 | AB26: =SUM(D26,F26,H26,J26,L26,N26,P26,R26,T26,V26,X26) -> 150000
A27: 25 | B27: مخالفة العلامات المرورية الشاخصة او الارضية | C27: 1 | D27: 50000 | E27: 6 | F27: 300000 | Y27: =SUM(C27,E27,G27,I27,K27,M27,O27,Q27,S27,U27,W27) -> 7 | AB27: =SUM(D27,F27,H27,J27,L27,N27,P27,R27,T27,V27,X27) -> 350000
A28: 26 | B28: عدم التنبيه بالإشارة قبل مسافة كافية عند الاستدارة او الوقوف | Y28: =SUM(C28,E28,G28,I28,K28,M28,O28,Q28,S28,U28,W28) -> 0 | AB28: =SUM(D28,F28,H28,J28,L28,N28,P28,R28,T28,V28,X28) -> 0
A29: 27 | B29: تحريك المركبة قبل التأكد من خلو جهة المرور من المركبات | Y29: =SUM(C29,E29,G29,I29,K29,M29,O29,Q29,S29,U29,W29) -> 0 | AB29: =SUM(D29,F29,H29,J29,L29,N29,P29,R29,T29,V29,X29) -> 0
A30: 28 | B30: قيادة(عجلة حمل او زراعية او انشائية او الدراجات النارية المحورة) التي تسير على الجانب الايسر من الطريق | E30: 3 | F30: 150000 | Y30: =SUM(C30,E30,G30,I30,K30,M30,O30,Q30,S30,U30,W30) -> 3 | AB30: =SUM(D30,F30,H30,J30,L30,N30,P30,R30,T30,V30,X30) -> 150000
A31: 29 | B31: التسبب بالازدحام لأي سبب كان | E31: 1 | F31: 50000 | I31: 4 | J31: 200000 | Y31: =SUM(C31,E31,G31,I31,K31,M31,O31,Q31,S31,U31,W31) -> 5 | AB31: =SUM(D31,F31,H31,J31,L31,N31,P31,R31,T31,V31,X31) -> 250000
A32: 30 | B32: رمي النفايات والاوراق والسكائر في الشوارع | Y32: =SUM(C32,E32,G32,I32,K32,M32,O32,Q32,S32,U32,W32) -> 0 | AB32: =SUM(D32,F32,H32,J32,L32,N32,P32,R32,T32,V32,X32) -> 0
A33: 31 | B33: تجاوز عدد ركاب الحافلة للعدد المرخص به | Y33: =SUM(C33,E33,G33,I33,K33,M33,O33,Q33,S33,U33,W33) -> 0 | AB33: =SUM(D33,F33,H33,J33,L33,N33,P33,R33,T33,V33,X33) -> 0
A34: 32 | B34: اخراج الرؤوس والابدان من النوافذ في الحافلة | Y34: =SUM(C34,E34,G34,I34,K34,M34,O34,Q34,S34,U34,W34) -> 0 | AB34: =SUM(D34,F34,H34,J34,L34,N34,P34,R34,T34,V34,X34) -> 0
A35: 33 | B35: عدم انارة الحافلة من الداخل بين غروب الشمس وشروقها وعند الضرورة | Y35: =SUM(C35,E35,G35,I35,K35,M35,O35,Q35,S35,U35,W35) -> 0 | AB35: =SUM(D35,F35,H35,J35,L35,N35,P35,R35,T35,V35,X35) -> 0
A36: 34 | B36: الوقوف لأخذ الركاب او انزالهم في الاماكن الغير مخصصة للوقوف | Y36: =SUM(C36,E36,G36,I36,K36,M36,O36,Q36,S36,U36,W36) -> 0 | AB36: =SUM(D36,F36,H36,J36,L36,N36,P36,R36,T36,V36,X36) -> 0
A37: 35 | B37: التحدث مع الركاب اثناء سير الحالفة او الوقوف بجانب السائق | Y37: =SUM(C37,E37,G37,I37,K37,M37,O37,Q37,S37,U37,W37) -> 0 | AB37: =SUM(D37,F37,H37,J37,L37,N37,P37,R37,T37,V37,X37) -> 0
A38: 36 | B38: رفض ركوب على استعداد لدفع التعريفة المقررة اذا لم تكم المركبة مستكملة عدد الركاب المرخص به | Y38: =SUM(C38,E38,G38,I38,K38,M38,O38,Q38,S38,U38,W38) -> 0 | AB38: =SUM(D38,F38,H38,J38,L38,N38,P38,R38,T38,V38,X38) -> 0
A39: 37 | B39: عدم تثبيت اعلان يوضح عدد الاشخاص المرخص به وان المركبة للأجرة | Y39: =SUM(C39,E39,G39,I39,K39,M39,O39,Q39,S39,U39,W39) -> 0 | AB39: =SUM(D39,F39,H39,J39,L39,N39,P39,R39,T39,V39,X39) -> 0
A40: 38 | B40: عدم تفتيش الحافلة وعدم تسليم الامانة الى اقرب مركز شرطة خلال (24) ساعة | Y40: =SUM(C40,E40,G40,I40,K40,M40,O40,Q40,S40,U40,W40) -> 0 | AB40: =SUM(D40,F40,H40,J40,L40,N40,P40,R40,T40,V40,X40) -> 0
A41: 39 | B41: الاشخاص اثناء عبور الشارع من غير المناطق المخصصة للعبور | Y41: =SUM(C41,E41,G41,I41,K41,M41,O41,Q41,S41,U41,W41) -> 0 | AB41: =SUM(D41,F41,H41,J41,L41,N41,P41,R41,T41,V41,X41) -> 0
...

Sheet مخالفات ومبالغ 
C3: موقف مديرية مرور محافظة نينوى للمخالفات ليوم | D3: =E3 -> 46116 | E3: =TODAY() -> 46116
B4: ت | C4: نوع المخالفة | D4: الملاحظات | G4: مجموع مبلغ المخالفة
D5: العدد/ الغرامات | E5: حجز مركبات | F5: حجز دراجات
B6: ='59مخالفة'!A3 -> 1 | C6: ='59مخالفة'!B3 -> عدم الامتثال للإشارة الضوئية او اشارة رجل المرور التنظيمية | D6: =SUM('59مخالفة'!Y3) -> 0 | E6: ='59مخالفة'!Z3 -> 0 | F6: ='59مخالفة'!AA3 -> 0 | G6: =SUM('59مخالفة'!AB3) -> 0
B7: ='59مخالفة'!A4 -> 2 | C7: ='59مخالفة'!B4 -> قيادة مركبة بإهمال ورعونة | D7: =SUM('59مخالفة'!Y4) -> 0 | E7: ='59مخالفة'!Z4 -> 0 | F7: ='59مخالفة'!AA4 -> 0 | G7: =SUM('59مخالفة'!AB4) -> 0
B8: ='59مخالفة'!A5 -> 3 | C8: ='59مخالفة'!B5 -> قيادة مركبة بسرعة تزيد عن السرعة المقررة قانونا | D8: =SUM('59مخالفة'!Y5) -> 0 | E8: ='59مخالفة'!Z5 -> 0 | F8: ='59مخالفة'!AA5 -> 0 | G8: =SUM('59مخالفة'!AB5) -> 0
B9: ='59مخالفة'!A6 -> 4 | C9: ='59مخالفة'!B6 -> مخالفة قواعد السير والمرور على الطرق السريع | D9: =SUM('59مخالفة'!Y6) -> 0 | E9: ='59مخالفة'!Z6 -> 0 | F9: ='59مخالفة'!AA6 -> 0 | G9: =SUM('59مخالفة'!AB6) -> 0
B10: ='59مخالفة'!A7 -> 5 | C10: ='59مخالفة'!B7 -> السير عكس الاتجاه | D10: =SUM('59مخالفة'!Y7) -> 0 | E10: ='59مخالفة'!Z7 -> 0 | F10: ='59مخالفة'!AA7 -> 0 | G10: =SUM('59مخالفة'!AB7) -> 0
B11: ='59مخالفة'!A8 -> 6 | C11: ='59مخالفة'!B8 -> الزجاج المضلل والستائر | D11: =SUM('59مخالفة'!Y8) -> 0 | E11: ='59مخالفة'!Z8 -> 0 | F11: ='59مخالفة'!AA8 -> 0 | G11: =SUM('59مخالفة'!AB8) -> 0
B12: ='59مخالفة'!A9 -> 7 | C12: ='59مخالفة'!B9 -> عدم تثبيت لوحات مفردة او مزدوجة (بدون لوحة تسجيل) | D12: =SUM('59مخالفة'!Y9) -> 0 | E12: ='59مخالفة'!Z9 -> 0 | F12: ='59مخالفة'!AA9 -> 0 | G12: =SUM('59مخالفة'!AB9) -> 0
B13: ='59مخالفة'!A10 -> 8 | C13: ='59مخالفة'!B10 -> عدم وضع غطاء الحمولة | D13: =SUM('59مخالفة'!Y10) -> 0 | E13: ='59مخالفة'!Z10 -> 0 | F13: ='59مخالفة'!AA10 -> 0 | G13: =SUM('59مخالفة'!AB10) -> 0
B14: ='59مخالفة'!A11 -> 9 | C14: ='59مخالفة'!B11 -> ارتفاع الحمولة | D14: =SUM('59مخالفة'!Y11) -> 15 | E14: ='59مخالفة'!Z11 -> 0 | F14: ='59مخالفة'!AA11 -> 0 | G14: =SUM('59مخالفة'!AB11) -> 1400000
B15: ='59مخالفة'!A12 -> 10 | C15: ='59مخالفة'!B12 -> عدم مراجعة البائع او المشتري لنقل ملكية المركبة خلال (30) يوم | D15: =SUM('59مخالفة'!Y12) -> 0 | E15: ='59مخالفة'!Z12 -> 0 | F15: ='59مخالفة'!AA12 -> 0 | G15: =SUM('59مخالفة'!AB12) -> 0
B16: ='59مخالفة'!A13 -> 11 | C16: ='59مخالفة'!B13 -> تنظيم اكثر من عقد واحد للمركبة ذاتها من قبل البائع | D16: =SUM('59مخالفة'!Y13) -> 0 | E16: ='59مخالفة'!Z13 -> 0 | F16: ='59مخالفة'!AA13 -> 0 | G16: =SUM('59مخالفة'!AB13) -> 0
B17: ='59مخالفة'!A14 -> 12 | C17: ='59مخالفة'!B14 -> قيادة مركبة بإجازة سوق غير مختصة بنوع المركبة | D17: =SUM('59مخالفة'!Y14) -> 41 | E17: ='59مخالفة'!Z14 -> 0 | F17: ='59مخالفة'!AA14 -> 0 | G17: =SUM('59مخالفة'!AB14) -> 2050000
... B61: ='59مخالفة'!A58 -> 56 | C61: ='59مخالفة'!B58 -> مخالفة بيان رقم (5) لسنة 2020 (الزوجي الفردي ) | D61: =SUM('59مخالفة'!Y58) -> 0 | E61: ='59مخالفة'!Z58 -> 0 | F61: ='59مخالفة'!AA58 -> 0 | G61: =SUM('59مخالفة'!AB58) -> 0
B62: ='59مخالفة'!A59 -> 57 | C62: حجز مركبات الفحص المؤقت | D62: =SUM('59مخالفة'!Y59) -> 0 | E62: ='59مخالفة'!Z59 -> 0 | F62: ='59مخالفة'!AA59 -> 0 | G62: =SUM('59مخالفة'!AB59) -> 0
B63: ='59مخالفة'!A60 -> 58 | C63: م ب رقم (1) لسنة 2012 قيادة الدراجات النارية من الساعة 6 مساءا لغاية 6 صباحا. استقلال الدراجة النارية من قبل شخصين | D63: =SUM('59مخالفة'!Y60) -> 0 | G63: =SUM('59مخالفة'!AB60) -> 0
B64: ='59مخالفة'!A61 -> 59 | C64: بيان رقم (4) يمنع وقوف المركبات على الارصفة | D64: =SUM('59مخالفة'!Y61) -> 0 | E64: ='59مخالفة'!Z61 -> 0 | F64: ='59مخالفة'!AA61 -> 0 | G64: =SUM('59مخالفة'!AB61) -> 0
C65: ='59مخالفة'!B62 -> مجموع المخالفات المرورية | D65: =SUM(D6:D64) -> 443 | E65: ='59مخالفة'!Z62 -> 0 | F65: ='59مخالفة'!AA62 -> 0 | G65: =SUM(G6:G64) -> 22950000
